<robot name="inertiabot3" >
    <link name="leg_A">
        <inertial>
            <origin rpy="0 0 0" xyz="0.0 0.0 0.0"/>
            <mass value="1.0"/>
            <inertia ixx="1.0" ixy="0.0" ixz="0.0" iyy="1.0" iyz="0.0" izz="1.0"/>
        </inertial>
        <visual>
            <origin rpy="0 0 0" xyz="0.0 0 0.0"/>
            <geometry name="leg_A_visual">
                <!--mesh filename="sr_description/arm/model/elbow_flex.dae" scale="0.001 0.001 0.001"/-->
                <box size="0.03 0.03 0.10"/>
            </geometry>
            <material name="Grey"/>
        </visual>
        <collision>
            <origin rpy="0 0 0" xyz="0.0 0.0 0.0"/>
            <geometry name="leg_A_collision">
                <box size="0.03 0.03 0.10"/>
            </geometry>
        </collision>
    </link>
    <link name="body">
        <inertial>
            <origin rpy="0 0 0" xyz="0.0 0.0 0.0"/>
            <mass value="1.0"/>
            <inertia ixx="1.0" ixy="0.0" ixz="0.0" iyy="1.0" iyz="0.0" izz="1.0"/>
        </inertial>
        <visual>
            <origin rpy="0 0 0" xyz="0.0 0 0.0"/>
            <geometry name="body_visual">
                <!--mesh filename="sr_description/arm/model/elbow_flex.dae" scale="0.001 0.001 0.001"/-->
                <box size="0.04 0.04 0.10"/>
            </geometry>
            <material name="Grey"/>
        </visual>
        <collision>
            <origin rpy="0 0 0" xyz="0.0 0.0 0.0"/>
            <geometry name="body_collision">
                <box size="0.04 0.04 0.10"/>
            </geometry>
        </collision>
    </link>
    <link name="leg_B">
        <inertial>
            <origin rpy="0 0 0" xyz="0.0 0.0 0.0"/>
            <mass value="1.0"/>
            <inertia ixx="1.0" ixy="0.0" ixz="0.0" iyy="1.0" iyz="0.0" izz="1.0"/>
        </inertial>
        <visual>
            <origin rpy="0 0 0" xyz="0.0 0 0.0"/>
            <geometry name="leg_B_visual">
                <!--mesh filename="sr_description/arm/model/elbow_flex.dae" scale="0.001 0.001 0.001"/-->
                <box size="0.03 0.03 0.10"/>
            </geometry>
            <material name="Grey"/>
        </visual>
        <collision>
            <origin rpy="0 0 0" xyz="0.0 0.0 0.0"/>
            <geometry name="leg_B_collision">
                <box size="0.03 0.03 0.10"/>
            </geometry>
        </collision>
    </link>

    <joint name="HipA" type="revolute">
        <parent link="body"/>
        <child link="leg_A"/>
        <origin rpy="0.0 0.0 0.0" xyz="0.0 0.0 -0.125"/>
        <axis xyz="0 1 0"/>
        <limit effort="10" lower="-1.57079632679" upper="1.57079632679" velocity="1.0"/>
        <dynamics damping="10.5"/>
    </joint>
    <joint name="HipB" type="revolute">
        <parent link="body"/>
        <child link="leg_B"/>
        <origin rpy="0.0 0.0 0.0" xyz="0.0 0.0 0.125"/>
        <axis xyz="0 1 0"/>
        <limit effort="10" lower="-1.57079632679" upper="1.57079632679" velocity="1.0"/>
        <dynamics damping="10.5"/>
    </joint>
    
    
    <material name="Blue">
        <color rgba="0.0 0.0 0.8 1.0"/>
    </material>
    <material name="Green">
        <color rgba="0.0 0.8 0.0 1.0"/>
    </material>
    <material name="Grey">
        <color rgba="0.2 0.2 0.2 1.0"/>
    </material>
    <material name="LightGrey">
        <color rgba="0.6 0.6 0.6 1.0"/>
    </material>
    <material name="Red">
        <color rgba="0.8 0.0 0.0 1.0"/>
    </material>
    <material name="White">
        <color rgba="1.0 1.0 1.0 1.0"/>
    </material>
</robot>