<?xml version="1.0" ?>
<!-- =================================================================================== -->
<!-- |    This document was autogenerated by xacro from jaemiHubo.xacro                | -->
<!-- |    EDITING THIS FILE BY HAND IS NOT RECOMMENDED                                 | -->
<!-- =================================================================================== -->
<robot name="jaemiHubo" xmlns:xacro="http://www.ros.org/wiki/xacro">
  <link name="Torso">
    <inertial>
      <mass value="7.95748"/>
      <inertia ixx="0.0835642" ixy="-6.7976e-05" ixz="0.00249373" iyy="0.0522353" iyz="-0.00120721" izz="0.0757541"/>
      <origin xyz="0 0 0"/>
    </inertial>
    <visual>
      <geometry>
        <mesh filename="dae/Torso_vis.dae"/>
      </geometry>
      <material name="random">
        <color rgba="0.800000 0.800000 0.500000 1"/>
      </material>
    </visual>
    <collision>
      <geometry>
        <mesh filename="dae/Torso_col.dae"/>
      </geometry>
    </collision>
  </link>
  <link name="rightTorsoDummy">
</link>
  <link name="Body_RSP">
    <inertial>
      <mass value="0.696197"/>
      <inertia ixx="0.000915048" ixy="0.000172338" ixz="-2.72e-07" iyy="0.000937024" iyz="2.72e-07" izz="0.00128765"/>
      <origin xyz="0 0 0"/>
    </inertial>
    <visual>
      <geometry>
        <mesh filename="dae/Body_RSP_vis.dae"/>
      </geometry>
      <material name="random">
        <color rgba="0.800000 0.800000 0.500000 1"/>
      </material>
    </visual>
    <collision>
      <geometry>
        <mesh filename="dae/Body_RSP_col.dae"/>
      </geometry>
    </collision>
  </link>
  <link name="Body_RSR">
    <inertial>
      <mass value="0.34818"/>
      <inertia ixx="0.000273479" ixy="-7.678e-06" ixz="9.906e-06" iyy="0.000247752" iyz="1.0681e-05" izz="0.000216759"/>
      <origin xyz="0.0173759 -0.0564627 -2.143e-06"/>
    </inertial>
    <visual>
      <geometry>
        <mesh filename="dae/Body_RSR_vis.dae"/>
      </geometry>
      <material name="random">
        <color rgba="0.800000 0.800000 0.500000 1"/>
      </material>
    </visual>
    <collision>
      <geometry>
        <mesh filename="dae/Body_RSR_col.dae"/>
      </geometry>
    </collision>
  </link>
  <link name="Body_RSY">
    <inertial>
      <mass value="1.40749"/>
      <inertia ixx="1" ixy="0" ixz="0" iyy="1" iyz="0" izz="1"/>
      <origin xyz="-0.0325444 0.00240206 -0.00436064"/>
    </inertial>
    <visual>
      <geometry>
        <mesh filename="dae/Body_RSY_vis.dae"/>
      </geometry>
      <material name="random">
        <color rgba="0.800000 0.800000 0.500000 1"/>
      </material>
    </visual>
    <collision>
      <geometry>
        <mesh filename="dae/Body_RSY_col.dae"/>
      </geometry>
    </collision>
  </link>
  <link name="Body_REP">
    <inertial>
      <mass value="0.090349"/>
      <inertia ixx="6.7021e-05" ixy="2.584e-06" ixz="-1.3385e-05" iyy="7.5166e-05" iyz="4.623e-06" izz="7.7705e-05"/>
      <origin xyz="0.00750642 0.00188892 -0.0897126"/>
    </inertial>
    <visual>
      <geometry>
        <mesh filename="dae/Body_REP_vis.dae"/>
      </geometry>
      <material name="random">
        <color rgba="0.800000 0.800000 0.500000 1"/>
      </material>
    </visual>
    <collision>
      <geometry>
        <mesh filename="dae/Body_REP_col.dae"/>
      </geometry>
    </collision>
  </link>
  <link name="Body_RWY">
    <inertial>
      <mass value="0.278224"/>
      <inertia ixx="0.000458115" ixy="4.01e-07" ixz="-1.5682e-05" iyy="0.000449915" iyz="-5.9e-08" izz="0.000200816"/>
      <origin xyz="-0.0137713 0.00656247 -0.0197353"/>
    </inertial>
    <visual>
      <geometry>
        <mesh filename="dae/Body_RWY_vis.dae"/>
      </geometry>
      <material name="random">
        <color rgba="0.800000 0.800000 0.500000 1"/>
      </material>
    </visual>
    <collision>
      <geometry>
        <mesh filename="dae/Body_RWY_col.dae"/>
      </geometry>
    </collision>
  </link>
  <link name="rightUJoint">
    <inertial>
      <mass value="0.00301705"/>
      <inertia ixx="1" ixy="0" ixz="0" iyy="1" iyz="0" izz="1"/>
      <origin xyz="-0.00337273 3.3462e-05 -0.039374"/>
    </inertial>
    <visual>
      <geometry>
        <mesh filename="dae/rightUJoint_vis.dae"/>
      </geometry>
      <material name="random">
        <color rgba="0.800000 0.800000 0.500000 1"/>
      </material>
    </visual>
    <collision>
      <geometry>
        <mesh filename="dae/rightUJoint_col.dae"/>
      </geometry>
    </collision>
  </link>
  <link name="rightPalmDummy">
</link>
  <link name="rightPalm">
    <inertial>
      <mass value="0.164998"/>
      <inertia ixx="0.000243946" ixy="1.1081e-05" ixz="-7.4294e-05" iyy="0.000268875" iyz="6.133e-05" izz="0.00017683"/>
      <origin xyz="0 0 0"/>
    </inertial>
    <visual>
      <geometry>
        <mesh filename="dae/rightPalm_vis.dae"/>
      </geometry>
      <material name="random">
        <color rgba="0.800000 0.800000 0.500000 1"/>
      </material>
    </visual>
  </link>
  <link name="rightThumbProximal">
    <inertial>
      <mass value="0.012"/>
      <inertia ixx="1" ixy="0" ixz="0" iyy="1" iyz="0" izz="1"/>
      <origin xyz="0 0 0"/>
    </inertial>
    <visual>
      <geometry>
        <mesh filename="dae/rightThumbProximal_vis.dae"/>
      </geometry>
      <material name="random">
        <color rgba="0.800000 0.800000 0.500000 1"/>
      </material>
    </visual>
  </link>
  <link name="rightThumbMedial">
    <inertial>
      <mass value="0.006"/>
      <inertia ixx="1" ixy="0" ixz="0" iyy="1" iyz="0" izz="1"/>
      <origin xyz="0.0216568 0.00565715 1.2556e-10"/>
    </inertial>
    <visual>
      <geometry>
        <mesh filename="dae/rightThumbMedial_vis.dae"/>
      </geometry>
      <material name="random">
        <color rgba="0.800000 0.800000 0.500000 1"/>
      </material>
    </visual>
  </link>
  <link name="rightThumbDistal">
    <inertial>
      <mass value="0.01"/>
      <inertia ixx="1" ixy="0" ixz="0" iyy="1" iyz="0" izz="1"/>
      <origin xyz="0.011 0 0"/>
    </inertial>
    <visual>
      <geometry>
        <mesh filename="dae/rightThumbDistal_vis.dae"/>
      </geometry>
      <material name="random">
        <color rgba="0.800000 0.800000 0.500000 1"/>
      </material>
    </visual>
  </link>
  <link name="rightPinkyProximal">
    <inertial>
      <mass value="0.012"/>
      <inertia ixx="1" ixy="0" ixz="0" iyy="1" iyz="0" izz="1"/>
      <origin xyz="0 0 0"/>
    </inertial>
    <visual>
      <geometry>
        <mesh filename="dae/rightPinkyProximal_vis.dae"/>
      </geometry>
      <material name="random">
        <color rgba="0.800000 0.800000 0.500000 1"/>
      </material>
    </visual>
  </link>
  <link name="rightPinkyMedial">
    <inertial>
      <mass value="0.006"/>
      <inertia ixx="1" ixy="0" ixz="0" iyy="1" iyz="0" izz="1"/>
      <origin xyz="0.0159998 1.5446e-07 0.0650062"/>
    </inertial>
    <visual>
      <geometry>
        <mesh filename="dae/rightPinkyMedial_vis.dae"/>
      </geometry>
      <material name="random">
        <color rgba="0.800000 0.800000 0.500000 1"/>
      </material>
    </visual>
  </link>
  <link name="rightPinkyDistal">
    <inertial>
      <mass value="0.01"/>
      <inertia ixx="1" ixy="0" ixz="0" iyy="1" iyz="0" izz="1"/>
      <origin xyz="0.011 0 0"/>
    </inertial>
    <visual>
      <geometry>
        <mesh filename="dae/rightPinkyDistal_vis.dae"/>
      </geometry>
      <material name="random">
        <color rgba="0.800000 0.800000 0.500000 1"/>
      </material>
    </visual>
  </link>
  <link name="rightRingProximal">
    <inertial>
      <mass value="0.012"/>
      <inertia ixx="1" ixy="0" ixz="0" iyy="1" iyz="0" izz="1"/>
      <origin xyz="0 0 0"/>
    </inertial>
    <visual>
      <geometry>
        <mesh filename="dae/rightRingProximal_vis.dae"/>
      </geometry>
      <material name="random">
        <color rgba="0.800000 0.800000 0.500000 1"/>
      </material>
    </visual>
  </link>
  <link name="rightRingMedial">
    <inertial>
      <mass value="0.006"/>
      <inertia ixx="1" ixy="0" ixz="0" iyy="1" iyz="0" izz="1"/>
      <origin xyz="0.0159998 1.54162e-07 0.0460042"/>
    </inertial>
    <visual>
      <geometry>
        <mesh filename="dae/rightRingMedial_vis.dae"/>
      </geometry>
      <material name="random">
        <color rgba="0.800000 0.800000 0.500000 1"/>
      </material>
    </visual>
  </link>
  <link name="rightRingDistal">
    <inertial>
      <mass value="0.01"/>
      <inertia ixx="1" ixy="0" ixz="0" iyy="1" iyz="0" izz="1"/>
      <origin xyz="0.011 0 0"/>
    </inertial>
    <visual>
      <geometry>
        <mesh filename="dae/rightRingDistal_vis.dae"/>
      </geometry>
      <material name="random">
        <color rgba="0.800000 0.800000 0.500000 1"/>
      </material>
    </visual>
  </link>
  <link name="rightMiddleProximal">
    <inertial>
      <mass value="0.012"/>
      <inertia ixx="1" ixy="0" ixz="0" iyy="1" iyz="0" izz="1"/>
      <origin xyz="0 0 0"/>
    </inertial>
    <visual>
      <geometry>
        <mesh filename="dae/rightMiddleProximal_vis.dae"/>
      </geometry>
      <material name="random">
        <color rgba="0.800000 0.800000 0.500000 1"/>
      </material>
    </visual>
  </link>
  <link name="rightMiddleMedial">
    <inertial>
      <mass value="0.006"/>
      <inertia ixx="1" ixy="0" ixz="0" iyy="1" iyz="0" izz="1"/>
      <origin xyz="0.0159998 1.53863e-07 0.0269662"/>
    </inertial>
    <visual>
      <geometry>
        <mesh filename="dae/rightMiddleMedial_vis.dae"/>
      </geometry>
      <material name="random">
        <color rgba="0.800000 0.800000 0.500000 1"/>
      </material>
    </visual>
  </link>
  <link name="rightMiddleDistal">
    <inertial>
      <mass value="0.01"/>
      <inertia ixx="1" ixy="0" ixz="0" iyy="1" iyz="0" izz="1"/>
      <origin xyz="0.011 0 0"/>
    </inertial>
    <visual>
      <geometry>
        <mesh filename="dae/rightMiddleDistal_vis.dae"/>
      </geometry>
      <material name="random">
        <color rgba="0.800000 0.800000 0.500000 1"/>
      </material>
    </visual>
  </link>
  <link name="rightIndexProximal">
    <inertial>
      <mass value="0.012"/>
      <inertia ixx="1" ixy="0" ixz="0" iyy="1" iyz="0" izz="1"/>
      <origin xyz="0 0 0"/>
    </inertial>
    <visual>
      <geometry>
        <mesh filename="dae/rightIndexProximal_vis.dae"/>
      </geometry>
      <material name="random">
        <color rgba="0.800000 0.800000 0.500000 1"/>
      </material>
    </visual>
  </link>
  <link name="rightIndexMedial">
    <inertial>
      <mass value="0.006"/>
      <inertia ixx="1" ixy="0" ixz="0" iyy="1" iyz="0" izz="1"/>
      <origin xyz="0.0159998 1.53566e-07 0.00800013"/>
    </inertial>
    <visual>
      <geometry>
        <mesh filename="dae/rightIndexMedial_vis.dae"/>
      </geometry>
      <material name="random">
        <color rgba="0.800000 0.800000 0.500000 1"/>
      </material>
    </visual>
  </link>
  <link name="rightIndexDistal">
    <inertial>
      <mass value="0.01"/>
      <inertia ixx="1" ixy="0" ixz="0" iyy="1" iyz="0" izz="1"/>
      <origin xyz="0.011 0 0"/>
    </inertial>
    <visual>
      <geometry>
        <mesh filename="dae/rightIndexDistal_vis.dae"/>
      </geometry>
      <material name="random">
        <color rgba="0.800000 0.800000 0.500000 1"/>
      </material>
    </visual>
  </link>
  <link name="leftTorsoDummy">
</link>
  <link name="Body_LSP">
    <inertial>
      <mass value="0.696197"/>
      <inertia ixx="0.000915048" ixy="-0.000172338" ixz="-2.72e-07" iyy="0.000937024" iyz="-2.72e-07" izz="0.00128765"/>
      <origin xyz="0 0 0"/>
    </inertial>
    <visual>
      <geometry>
        <mesh filename="dae/Body_LSP_vis.dae"/>
      </geometry>
      <material name="random">
        <color rgba="0.800000 0.800000 0.500000 1"/>
      </material>
    </visual>
    <collision>
      <geometry>
        <mesh filename="dae/Body_LSP_col.dae"/>
      </geometry>
    </collision>
  </link>
  <link name="Body_LSR">
    <inertial>
      <mass value="0.34818"/>
      <inertia ixx="0.000273479" ixy="7.678e-06" ixz="9.906e-06" iyy="0.000247752" iyz="-1.0681e-05" izz="0.000216759"/>
      <origin xyz="0.0173759 0.0564627 -2.143e-06"/>
    </inertial>
    <visual>
      <geometry>
        <mesh filename="dae/Body_LSR_vis.dae"/>
      </geometry>
      <material name="random">
        <color rgba="0.800000 0.800000 0.500000 1"/>
      </material>
    </visual>
    <collision>
      <geometry>
        <mesh filename="dae/Body_LSR_col.dae"/>
      </geometry>
    </collision>
  </link>
  <link name="Body_LSY">
    <inertial>
      <mass value="1.40749"/>
      <inertia ixx="1" ixy="0" ixz="0" iyy="1" iyz="0" izz="1"/>
      <origin xyz="-0.0325444 -0.00240206 -0.00436064"/>
    </inertial>
    <visual>
      <geometry>
        <mesh filename="dae/Body_LSY_vis.dae"/>
      </geometry>
      <material name="random">
        <color rgba="0.800000 0.800000 0.500000 1"/>
      </material>
    </visual>
    <collision>
      <geometry>
        <mesh filename="dae/Body_LSY_col.dae"/>
      </geometry>
    </collision>
  </link>
  <link name="Body_LEP">
    <inertial>
      <mass value="0.090349"/>
      <inertia ixx="6.7021e-05" ixy="-2.584e-06" ixz="-1.3385e-05" iyy="7.5166e-05" iyz="-4.623e-06" izz="7.7705e-05"/>
      <origin xyz="0.00750642 -0.00188892 -0.0897126"/>
    </inertial>
    <visual>
      <geometry>
        <mesh filename="dae/Body_LEP_vis.dae"/>
      </geometry>
      <material name="random">
        <color rgba="0.800000 0.800000 0.500000 1"/>
      </material>
    </visual>
    <collision>
      <geometry>
        <mesh filename="dae/Body_LEP_col.dae"/>
      </geometry>
    </collision>
  </link>
  <link name="Body_LWY">
    <inertial>
      <mass value="0.278224"/>
      <inertia ixx="0.000458115" ixy="-4.01e-07" ixz="-1.5682e-05" iyy="0.000449915" iyz="5.9e-08" izz="0.000200816"/>
      <origin xyz="-0.0137713 -0.00656247 -0.0197353"/>
    </inertial>
    <visual>
      <geometry>
        <mesh filename="dae/Body_LWY_vis.dae"/>
      </geometry>
      <material name="random">
        <color rgba="0.800000 0.800000 0.500000 1"/>
      </material>
    </visual>
    <collision>
      <geometry>
        <mesh filename="dae/Body_LWY_col.dae"/>
      </geometry>
    </collision>
  </link>
  <link name="leftUJoint">
    <inertial>
      <mass value="0.00301705"/>
      <inertia ixx="1" ixy="0" ixz="0" iyy="1" iyz="0" izz="1"/>
      <origin xyz="-0.00337273 -3.3462e-05 -0.039374"/>
    </inertial>
    <visual>
      <geometry>
        <mesh filename="dae/leftUJoint_vis.dae"/>
      </geometry>
      <material name="random">
        <color rgba="0.800000 0.800000 0.500000 1"/>
      </material>
    </visual>
    <collision>
      <geometry>
        <mesh filename="dae/leftUJoint_col.dae"/>
      </geometry>
    </collision>
  </link>
  <link name="leftPalmDummy">
</link>
  <link name="leftPalm">
    <inertial>
      <mass value="0.164998"/>
      <inertia ixx="0.000243946" ixy="1.1081e-05" ixz="-7.4294e-05" iyy="0.000268875" iyz="6.133e-05" izz="0.00017683"/>
      <origin xyz="0 0 0"/>
    </inertial>
    <visual>
      <geometry>
        <mesh filename="dae/leftPalm_vis.dae"/>
      </geometry>
      <material name="random">
        <color rgba="0.800000 0.800000 0.500000 1"/>
      </material>
    </visual>
  </link>
  <link name="leftThumbProximal">
    <inertial>
      <mass value="0.012"/>
      <inertia ixx="1" ixy="0" ixz="0" iyy="1" iyz="0" izz="1"/>
      <origin xyz="0 0 0"/>
    </inertial>
    <visual>
      <geometry>
        <mesh filename="dae/leftThumbProximal_vis.dae"/>
      </geometry>
      <material name="random">
        <color rgba="0.800000 0.800000 0.500000 1"/>
      </material>
    </visual>
  </link>
  <link name="leftThumbMedial">
    <inertial>
      <mass value="0.006"/>
      <inertia ixx="1" ixy="0" ixz="0" iyy="1" iyz="0" izz="1"/>
      <origin xyz="0.0159998 1.5344e-07 0.00800013"/>
    </inertial>
    <visual>
      <geometry>
        <mesh filename="dae/leftThumbMedial_vis.dae"/>
      </geometry>
      <material name="random">
        <color rgba="0.800000 0.800000 0.500000 1"/>
      </material>
    </visual>
  </link>
  <link name="leftThumbDistal">
    <inertial>
      <mass value="0.01"/>
      <inertia ixx="1" ixy="0" ixz="0" iyy="1" iyz="0" izz="1"/>
      <origin xyz="0.011 0 0"/>
    </inertial>
    <visual>
      <geometry>
        <mesh filename="dae/leftThumbDistal_vis.dae"/>
      </geometry>
      <material name="random">
        <color rgba="0.800000 0.800000 0.500000 1"/>
      </material>
    </visual>
  </link>
  <link name="leftPinkyProximal">
    <inertial>
      <mass value="0.012"/>
      <inertia ixx="1" ixy="0" ixz="0" iyy="1" iyz="0" izz="1"/>
      <origin xyz="0 0 0"/>
    </inertial>
    <visual>
      <geometry>
        <mesh filename="dae/leftPinkyProximal_vis.dae"/>
      </geometry>
      <material name="random">
        <color rgba="0.800000 0.800000 0.500000 1"/>
      </material>
    </visual>
  </link>
  <link name="leftPinkyMedial">
    <inertial>
      <mass value="0.006"/>
      <inertia ixx="1" ixy="0" ixz="0" iyy="1" iyz="0" izz="1"/>
      <origin xyz="0.0159998 1.5344e-07 -0.0650062"/>
    </inertial>
    <visual>
      <geometry>
        <mesh filename="dae/leftPinkyMedial_vis.dae"/>
      </geometry>
      <material name="random">
        <color rgba="0.800000 0.800000 0.500000 1"/>
      </material>
    </visual>
  </link>
  <link name="leftPinkyDistal">
    <inertial>
      <mass value="0.01"/>
      <inertia ixx="1" ixy="0" ixz="0" iyy="1" iyz="0" izz="1"/>
      <origin xyz="0.011 0 0"/>
    </inertial>
    <visual>
      <geometry>
        <mesh filename="dae/leftPinkyDistal_vis.dae"/>
      </geometry>
      <material name="random">
        <color rgba="0.800000 0.800000 0.500000 1"/>
      </material>
    </visual>
  </link>
  <link name="leftRingProximal">
    <inertial>
      <mass value="0.012"/>
      <inertia ixx="1" ixy="0" ixz="0" iyy="1" iyz="0" izz="1"/>
      <origin xyz="0 0 0"/>
    </inertial>
    <visual>
      <geometry>
        <mesh filename="dae/leftRingProximal_vis.dae"/>
      </geometry>
      <material name="random">
        <color rgba="0.800000 0.800000 0.500000 1"/>
      </material>
    </visual>
  </link>
  <link name="leftRingMedial">
    <inertial>
      <mass value="0.006"/>
      <inertia ixx="1" ixy="0" ixz="0" iyy="1" iyz="0" izz="1"/>
      <origin xyz="0.0159998 1.5344e-07 -0.0460042"/>
    </inertial>
    <visual>
      <geometry>
        <mesh filename="dae/leftRingMedial_vis.dae"/>
      </geometry>
      <material name="random">
        <color rgba="0.800000 0.800000 0.500000 1"/>
      </material>
    </visual>
  </link>
  <link name="leftRingDistal">
    <inertial>
      <mass value="0.01"/>
      <inertia ixx="1" ixy="0" ixz="0" iyy="1" iyz="0" izz="1"/>
      <origin xyz="0.011 0 0"/>
    </inertial>
    <visual>
      <geometry>
        <mesh filename="dae/leftRingDistal_vis.dae"/>
      </geometry>
      <material name="random">
        <color rgba="0.800000 0.800000 0.500000 1"/>
      </material>
    </visual>
  </link>
  <link name="leftMiddleProximal">
    <inertial>
      <mass value="0.012"/>
      <inertia ixx="1" ixy="0" ixz="0" iyy="1" iyz="0" izz="1"/>
      <origin xyz="0 0 0"/>
    </inertial>
    <visual>
      <geometry>
        <mesh filename="dae/leftMiddleProximal_vis.dae"/>
      </geometry>
      <material name="random">
        <color rgba="0.800000 0.800000 0.500000 1"/>
      </material>
    </visual>
  </link>
  <link name="leftMiddleMedial">
    <inertial>
      <mass value="0.006"/>
      <inertia ixx="1" ixy="0" ixz="0" iyy="1" iyz="0" izz="1"/>
      <origin xyz="0.0159998 1.5344e-07 -0.0269662"/>
    </inertial>
    <visual>
      <geometry>
        <mesh filename="dae/leftMiddleMedial_vis.dae"/>
      </geometry>
      <material name="random">
        <color rgba="0.800000 0.800000 0.500000 1"/>
      </material>
    </visual>
  </link>
  <link name="leftMiddleDistal">
    <inertial>
      <mass value="0.01"/>
      <inertia ixx="1" ixy="0" ixz="0" iyy="1" iyz="0" izz="1"/>
      <origin xyz="0.011 0 0"/>
    </inertial>
    <visual>
      <geometry>
        <mesh filename="dae/leftMiddleDistal_vis.dae"/>
      </geometry>
      <material name="random">
        <color rgba="0.800000 0.800000 0.500000 1"/>
      </material>
    </visual>
  </link>
  <link name="leftIndexProximal">
    <inertial>
      <mass value="0.012"/>
      <inertia ixx="1" ixy="0" ixz="0" iyy="1" iyz="0" izz="1"/>
      <origin xyz="0 0 0"/>
    </inertial>
    <visual>
      <geometry>
        <mesh filename="dae/leftIndexProximal_vis.dae"/>
      </geometry>
      <material name="random">
        <color rgba="0.800000 0.800000 0.500000 1"/>
      </material>
    </visual>
  </link>
  <link name="leftIndexMedial">
    <inertial>
      <mass value="0.006"/>
      <inertia ixx="1" ixy="0" ixz="0" iyy="1" iyz="0" izz="1"/>
      <origin xyz="0.0159998 1.5344e-07 -0.00800013"/>
    </inertial>
    <visual>
      <geometry>
        <mesh filename="dae/leftIndexMedial_vis.dae"/>
      </geometry>
      <material name="random">
        <color rgba="0.800000 0.800000 0.500000 1"/>
      </material>
    </visual>
  </link>
  <link name="leftIndexDistal">
    <inertial>
      <mass value="0.01"/>
      <inertia ixx="1" ixy="0" ixz="0" iyy="1" iyz="0" izz="1"/>
      <origin xyz="0.011 0 0"/>
    </inertial>
    <visual>
      <geometry>
        <mesh filename="dae/leftIndexDistal_vis.dae"/>
      </geometry>
      <material name="random">
        <color rgba="0.800000 0.800000 0.500000 1"/>
      </material>
    </visual>
  </link>
  <link name="HeadYaw">
    <visual>
      <geometry>
        <mesh filename="dae/HeadYaw_vis.dae"/>
      </geometry>
      <material name="random">
        <color rgba="0.800000 0.800000 0.500000 1"/>
      </material>
    </visual>
  </link>
  <link name="Head">
    <visual>
      <geometry>
        <mesh filename="dae/Head_vis.dae"/>
      </geometry>
      <material name="random">
        <color rgba="0.800000 0.800000 0.500000 1"/>
      </material>
    </visual>
    <collision>
      <geometry>
        <mesh filename="dae/Head_col.dae"/>
      </geometry>
    </collision>
  </link>
  <link name="Hip">
    <inertial>
      <mass value="4.43634"/>
      <inertia ixx="0.0227668" ixy="5.3624e-05" ixz="-0.000164219" iyy="0.00941822" iyz="-1.0039e-05" izz="0.0266105"/>
      <origin xyz="0 0 0"/>
    </inertial>
    <visual>
      <geometry>
        <mesh filename="dae/Hip_vis.dae"/>
      </geometry>
      <material name="random">
        <color rgba="0.800000 0.800000 0.500000 1"/>
      </material>
    </visual>
    <collision>
      <geometry>
        <mesh filename="dae/Hip_col.dae"/>
      </geometry>
    </collision>
  </link>
  <link name="hipDummyRight">
</link>
  <link name="rightHip">
    <inertial>
      <mass value="0.483119"/>
      <inertia ixx="0.000863427" ixy="-1.238e-06" ixz="4.2545e-05" iyy="0.00202964" iyz="-6.27e-07" izz="0.0014731"/>
      <origin xyz="0 0 0"/>
    </inertial>
    <visual>
      <geometry>
        <mesh filename="dae/rightHip_vis.dae"/>
      </geometry>
      <material name="random">
        <color rgba="0.800000 0.800000 0.500000 1"/>
      </material>
    </visual>
    <collision>
      <geometry>
        <mesh filename="dae/rightHip_col.dae"/>
      </geometry>
    </collision>
  </link>
  <link name="rightHipPitchRoll">
    <inertial>
      <mass value="2.64464"/>
      <inertia ixx="0.00438558" ixy="-0.000224243" ixz="-0.000447015" iyy="0.00463345" iyz="0.000377898" izz="0.00439864"/>
      <origin xyz="0.00678968 -6.3656e-05 -0.0537693"/>
    </inertial>
    <visual>
      <geometry>
        <mesh filename="dae/rightHipPitchRoll_vis.dae"/>
      </geometry>
      <material name="random">
        <color rgba="0.800000 0.800000 0.500000 1"/>
      </material>
    </visual>
    <collision>
      <geometry>
        <mesh filename="dae/rightHipPitchRoll_col.dae"/>
      </geometry>
    </collision>
  </link>
  <link name="rightKneeUpper">
    <inertial>
      <mass value="3.0988"/>
      <inertia ixx="0.0368448" ixy="-0.00025553" ixz="-0.000624748" iyy="0.0345571" iyz="-0.000952212" izz="0.00923802"/>
      <origin xyz="0.0138494 -0.0109015 -0.0119733"/>
    </inertial>
    <visual>
      <geometry>
        <mesh filename="dae/rightKneeUpper_vis.dae"/>
      </geometry>
      <material name="random">
        <color rgba="0.800000 0.800000 0.500000 1"/>
      </material>
    </visual>
    <collision>
      <geometry>
        <mesh filename="dae/rightKneeUpper_col.dae"/>
      </geometry>
    </collision>
  </link>
  <link name="rightKneeLower">
    <inertial>
      <mass value="1.5596"/>
      <inertia ixx="0.022012" ixy="-0.000117575" ixz="-0.000867941" iyy="0.020299" iyz="-0.00203718" izz="0.00504544"/>
      <origin xyz="0.0198678 -0.0587944 -0.188775"/>
    </inertial>
    <visual>
      <geometry>
        <mesh filename="dae/rightKneeLower_vis.dae"/>
      </geometry>
      <material name="random">
        <color rgba="0.800000 0.800000 0.500000 1"/>
      </material>
    </visual>
    <collision>
      <geometry>
        <mesh filename="dae/rightKneeLower_col.dae"/>
      </geometry>
    </collision>
  </link>
  <link name="rightAnklePitch">
    <inertial>
      <mass value="1.67492"/>
      <inertia ixx="0.00234229" ixy="-0.000114531" ixz="0.000316185" iyy="0.0030196" iyz="-0.000107388" izz="0.00284614"/>
      <origin xyz="0.0181205 0.013915 -0.152406"/>
    </inertial>
    <visual>
      <geometry>
        <mesh filename="dae/rightAnklePitch_vis.dae"/>
      </geometry>
      <material name="random">
        <color rgba="0.800000 0.800000 0.500000 1"/>
      </material>
    </visual>
    <collision>
      <geometry>
        <mesh filename="dae/rightAnklePitch_col.dae"/>
      </geometry>
    </collision>
  </link>
  <link name="rightFoot">
    <inertial>
      <mass value="0.525134"/>
      <inertia ixx="0.00129993" ixy="3.599e-06" ixz="-9.6266e-05" iyy="0.00270179" iyz="-2.6851e-05" izz="0.00275359"/>
      <origin xyz="0.0191505 0.0429579 0.00938076"/>
    </inertial>
    <visual>
      <geometry>
        <mesh filename="dae/rightFoot_vis.dae"/>
      </geometry>
      <material name="random">
        <color rgba="0.800000 0.800000 0.500000 1"/>
      </material>
    </visual>
    <collision>
      <geometry>
        <mesh filename="dae/rightFoot_col.dae"/>
      </geometry>
    </collision>
  </link>
  <link name="hipDummyLeft">
</link>
  <link name="leftHip">
    <inertial>
      <mass value="0.483119"/>
      <inertia ixx="0.000863427" ixy="1.238e-06" ixz="4.2545e-05" iyy="0.00202964" iyz="6.27e-07" izz="0.0014731"/>
      <origin xyz="0 0 0"/>
    </inertial>
    <visual>
      <geometry>
        <mesh filename="dae/leftHip_vis.dae"/>
      </geometry>
      <material name="random">
        <color rgba="0.800000 0.800000 0.500000 1"/>
      </material>
    </visual>
    <collision>
      <geometry>
        <mesh filename="dae/leftHip_col.dae"/>
      </geometry>
    </collision>
  </link>
  <link name="leftHipPitchRoll">
    <inertial>
      <mass value="2.64464"/>
      <inertia ixx="0.00438558" ixy="0.000224243" ixz="-0.000447015" iyy="0.00463345" iyz="-0.000377898" izz="0.00439864"/>
      <origin xyz="0.00678968 6.3656e-05 -0.0537693"/>
    </inertial>
    <visual>
      <geometry>
        <mesh filename="dae/leftHipPitchRoll_vis.dae"/>
      </geometry>
      <material name="random">
        <color rgba="0.800000 0.800000 0.500000 1"/>
      </material>
    </visual>
    <collision>
      <geometry>
        <mesh filename="dae/leftHipPitchRoll_col.dae"/>
      </geometry>
    </collision>
  </link>
  <link name="leftKneeUpper">
    <inertial>
      <mass value="3.0988"/>
      <inertia ixx="0.0368448" ixy="0.00025553" ixz="-0.000624748" iyy="0.0345571" iyz="0.000952212" izz="0.00923802"/>
      <origin xyz="0.0138494 0.0109015 -0.0119733"/>
    </inertial>
    <visual>
      <geometry>
        <mesh filename="dae/leftKneeUpper_vis.dae"/>
      </geometry>
      <material name="random">
        <color rgba="0.800000 0.800000 0.500000 1"/>
      </material>
    </visual>
    <collision>
      <geometry>
        <mesh filename="dae/leftKneeUpper_col.dae"/>
      </geometry>
    </collision>
  </link>
  <link name="leftKneeLower">
    <inertial>
      <mass value="1.5596"/>
      <inertia ixx="0.022012" ixy="0.000117575" ixz="-0.000867941" iyy="0.020299" iyz="0.00203718" izz="0.00504544"/>
      <origin xyz="0.0198678 0.0587944 -0.188775"/>
    </inertial>
    <visual>
      <geometry>
        <mesh filename="dae/leftKneeLower_vis.dae"/>
      </geometry>
      <material name="random">
        <color rgba="0.800000 0.800000 0.500000 1"/>
      </material>
    </visual>
    <collision>
      <geometry>
        <mesh filename="dae/leftKneeLower_col.dae"/>
      </geometry>
    </collision>
  </link>
  <link name="leftAnklePitch">
    <inertial>
      <mass value="1.67492"/>
      <inertia ixx="0.00234229" ixy="0.000114531" ixz="0.000316185" iyy="0.0030196" iyz="0.000107388" izz="0.00284614"/>
      <origin xyz="0.0181205 -0.013915 -0.152406"/>
    </inertial>
    <visual>
      <geometry>
        <mesh filename="dae/leftAnklePitch_vis.dae"/>
      </geometry>
      <material name="random">
        <color rgba="0.800000 0.800000 0.500000 1"/>
      </material>
    </visual>
    <collision>
      <geometry>
        <mesh filename="dae/leftAnklePitch_col.dae"/>
      </geometry>
    </collision>
  </link>
  <link name="leftFoot">
    <inertial>
      <mass value="0.525134"/>
      <inertia ixx="0.00129993" ixy="-3.599e-06" ixz="-9.6266e-05" iyy="0.00270179" iyz="2.6851e-05" izz="0.00275359"/>
      <origin xyz="0.0191505 -0.0429579 0.00938076"/>
    </inertial>
    <visual>
      <geometry>
        <mesh filename="dae/leftFoot_vis.dae"/>
      </geometry>
      <material name="random">
        <color rgba="0.800000 0.800000 0.500000 1"/>
      </material>
    </visual>
    <collision>
      <geometry>
        <mesh filename="dae/leftFoot_col.dae"/>
      </geometry>
    </collision>
  </link>
  <joint name="rightTorsoJoint" type="fixed">
    <origin rpy="0 -0 0" xyz="0.00549476 0.000506882 0.048924"/>
    <parent link="Torso"/>
    <child link="rightTorsoDummy"/>
    <limit effort="10" lower="0" upper="0" velocity="1"/>
  </joint>
  <joint name="RSP" type="revolute">
    <origin rpy="0 -0 0" xyz="0 -0.1425 0"/>
    <parent link="rightTorsoDummy"/>
    <child link="Body_RSP"/>
    <axis xyz="0 1 0"/>
    <limit effort="10" lower="-2.61799" upper="2.61799" velocity="1"/>
  </joint>
  <joint name="RSR" type="revolute">
    <origin rpy="0 -0 0" xyz="0.025 -0.072 0"/>
    <parent link="Body_RSP"/>
    <child link="Body_RSR"/>
    <axis xyz="1 0 0"/>
    <limit effort="10" lower="-3.14159" upper="0.174533" velocity="1"/>
  </joint>
  <joint name="RSY" type="revolute">
    <origin rpy="0 -0 0" xyz="-0.0269 0 -0.0245"/>
    <parent link="Body_RSR"/>
    <child link="Body_RSY"/>
    <axis xyz="0 0 1"/>
    <limit effort="10" lower="-2.74017" upper="2.74017" velocity="1"/>
  </joint>
  <joint name="REP" type="revolute">
    <origin rpy="0 -0 0" xyz="0.022279 -0.0115 -0.154441"/>
    <parent link="Body_RSY"/>
    <child link="Body_REP"/>
    <axis xyz="0 1 0"/>
    <limit effort="10" lower="-2.51327" upper="0.349066" velocity="1"/>
  </joint>
  <joint name="RWY" type="revolute">
    <origin rpy="0 -0 0" xyz="-0.022001 0.0115 -0.041"/>
    <parent link="Body_REP"/>
    <child link="Body_RWY"/>
    <axis xyz="0 0 1"/>
    <limit effort="10" lower="-2.79253" upper="2.79253" velocity="1"/>
  </joint>
  <joint name="RWR" type="revolute">
    <origin rpy="0 -0 0" xyz="0 0 -0.122"/>
    <parent link="Body_RWY"/>
    <child link="rightUJoint"/>
    <axis xyz="1 0 0"/>
    <limit effort="10" lower="-0.523599" upper="0.523599" velocity="1"/>
  </joint>
  <joint name="RWP" type="revolute">
    <origin rpy="0 -0 0" xyz="0 0 0"/>
    <parent link="rightUJoint"/>
    <child link="rightPalmDummy"/>
    <axis xyz="0 1 0"/>
    <limit effort="10" lower="-0.523599" upper="0.523599" velocity="1"/>
  </joint>
  <joint name="attachRightHand" type="fixed">
    <origin rpy="0 -0 0" xyz="-0.000123302 -0.00302904 -0.060093"/>
    <parent link="rightPalmDummy"/>
    <child link="rightPalm"/>
    <limit effort="10" lower="0" upper="0" velocity="1"/>
  </joint>
  <joint name="rightThumbKnuckle1" type="revolute">
    <origin rpy="-1.5708 -0.785398 0.785398" xyz="0.0211545 -0.000501556 0.0231108"/>
    <parent link="rightPalm"/>
    <child link="rightThumbProximal"/>
    <axis xyz="3.78941e-08 -1.56957e-08 -1"/>
    <limit effort="10" lower="-3.14" upper="3.14" velocity="1"/>
  </joint>
  <joint name="Knuckle210" type="revolute">
    <origin rpy="0 -0 0" xyz="0.0376568 0.00565715 1.2556e-10"/>
    <parent link="rightThumbProximal"/>
    <child link="rightThumbMedial"/>
    <axis xyz="0 0 -1"/>
    <limit effort="10" lower="-3.14" upper="3.14" velocity="1"/>
  </joint>
  <joint name="Knuckle311" type="revolute">
    <origin rpy="0 -0 0" xyz="0.022 0 0"/>
    <parent link="rightThumbMedial"/>
    <child link="rightThumbDistal"/>
    <axis xyz="0 0 -1"/>
    <limit effort="10" lower="-3.14" upper="3.14" velocity="1"/>
  </joint>
  <joint name="rightPinkyKnuckle1" type="revolute">
    <origin rpy="1.5708 0.785398 -2.35619" xyz="0.018385 -0.0301679 -0.00482959"/>
    <parent link="rightPalm"/>
    <child link="rightPinkyProximal"/>
    <axis xyz="3.78941e-08 -1.56957e-08 -1"/>
    <limit effort="10" lower="-3.14" upper="3.14" velocity="1"/>
  </joint>
  <joint name="Knuckle213" type="revolute">
    <origin rpy="0 -0 0" xyz="0.0319998 1.5446e-07 0.0650062"/>
    <parent link="rightPinkyProximal"/>
    <child link="rightPinkyMedial"/>
    <axis xyz="0 0 -1"/>
    <limit effort="10" lower="-3.14" upper="3.14" velocity="1"/>
  </joint>
  <joint name="Knuckle314" type="revolute">
    <origin rpy="0 -0 0" xyz="0.022 0 0"/>
    <parent link="rightPinkyMedial"/>
    <child link="rightPinkyDistal"/>
    <axis xyz="0 0 -1"/>
    <limit effort="10" lower="-3.14" upper="3.14" velocity="1"/>
  </joint>
  <joint name="rightRingKnuckle1" type="revolute">
    <origin rpy="1.5708 0.785398 -2.35619" xyz="0.0183853 -0.0301681 -0.00482959"/>
    <parent link="rightPalm"/>
    <child link="rightRingProximal"/>
    <axis xyz="3.78941e-08 -1.56957e-08 -1"/>
    <limit effort="10" lower="-3.14" upper="3.14" velocity="1"/>
  </joint>
  <joint name="Knuckle216" type="revolute">
    <origin rpy="0 -0 0" xyz="0.0319998 1.54162e-07 0.0460042"/>
    <parent link="rightRingProximal"/>
    <child link="rightRingMedial"/>
    <axis xyz="0 0 -1"/>
    <limit effort="10" lower="-3.14" upper="3.14" velocity="1"/>
  </joint>
  <joint name="Knuckle317" type="revolute">
    <origin rpy="0 -0 0" xyz="0.022 0 0"/>
    <parent link="rightRingMedial"/>
    <child link="rightRingDistal"/>
    <axis xyz="0 0 -1"/>
    <limit effort="10" lower="-3.14" upper="3.14" velocity="1"/>
  </joint>
  <joint name="rightMiddleKnuckle1" type="revolute">
    <origin rpy="1.5708 0.785398 -2.35619" xyz="0.0183855 -0.0301684 -0.00482959"/>
    <parent link="rightPalm"/>
    <child link="rightMiddleProximal"/>
    <axis xyz="3.78941e-08 -1.56957e-08 -1"/>
    <limit effort="10" lower="-3.14" upper="3.14" velocity="1"/>
  </joint>
  <joint name="Knuckle219" type="revolute">
    <origin rpy="0 -0 0" xyz="0.0319998 1.53863e-07 0.0269662"/>
    <parent link="rightMiddleProximal"/>
    <child link="rightMiddleMedial"/>
    <axis xyz="0 0 -1"/>
    <limit effort="10" lower="-3.14" upper="3.14" velocity="1"/>
  </joint>
  <joint name="Knuckle320" type="revolute">
    <origin rpy="0 -0 0" xyz="0.022 0 0"/>
    <parent link="rightMiddleMedial"/>
    <child link="rightMiddleDistal"/>
    <axis xyz="0 0 -1"/>
    <limit effort="10" lower="-3.14" upper="3.14" velocity="1"/>
  </joint>
  <joint name="rightIndexKnuckle1" type="revolute">
    <origin rpy="1.5708 0.785398 -2.35619" xyz="0.0183858 -0.0301686 -0.00482959"/>
    <parent link="rightPalm"/>
    <child link="rightIndexProximal"/>
    <axis xyz="3.78941e-08 -1.56957e-08 -1"/>
    <limit effort="10" lower="-3.14" upper="3.14" velocity="1"/>
  </joint>
  <joint name="Knuckle222" type="revolute">
    <origin rpy="0 -0 0" xyz="0.0319998 1.53566e-07 0.00800013"/>
    <parent link="rightIndexProximal"/>
    <child link="rightIndexMedial"/>
    <axis xyz="0 0 -1"/>
    <limit effort="10" lower="-3.14" upper="3.14" velocity="1"/>
  </joint>
  <joint name="Knuckle323" type="revolute">
    <origin rpy="0 -0 0" xyz="0.022 0 0"/>
    <parent link="rightIndexMedial"/>
    <child link="rightIndexDistal"/>
    <axis xyz="0 0 -1"/>
    <limit effort="10" lower="-3.14" upper="3.14" velocity="1"/>
  </joint>
  <joint name="leftTorsoJoint" type="fixed">
    <origin rpy="0 -0 0" xyz="0.00549476 0.000506882 0.048924"/>
    <parent link="Torso"/>
    <child link="leftTorsoDummy"/>
    <limit effort="10" lower="0" upper="0" velocity="1"/>
  </joint>
  <joint name="LSP" type="revolute">
    <origin rpy="0 -0 0" xyz="0 0.1425 0"/>
    <parent link="leftTorsoDummy"/>
    <child link="Body_LSP"/>
    <axis xyz="0 1 0"/>
    <limit effort="10" lower="-3.14159" upper="3.14159" velocity="1"/>
  </joint>
  <joint name="LSR" type="revolute">
    <origin rpy="0 -0 0" xyz="0.025 0.072 0"/>
    <parent link="Body_LSP"/>
    <child link="Body_LSR"/>
    <axis xyz="1 0 0"/>
    <limit effort="10" lower="-0.174533" upper="3.14159" velocity="1"/>
  </joint>
  <joint name="LSY" type="revolute">
    <origin rpy="0 -0 0" xyz="-0.0269 0 -0.0245"/>
    <parent link="Body_LSR"/>
    <child link="Body_LSY"/>
    <axis xyz="0 0 1"/>
    <limit effort="10" lower="-2.74017" upper="2.74017" velocity="1"/>
  </joint>
  <joint name="LEP" type="revolute">
    <origin rpy="0 -0 0" xyz="0.022279 0.0115 -0.154441"/>
    <parent link="Body_LSY"/>
    <child link="Body_LEP"/>
    <axis xyz="0 1 0"/>
    <limit effort="10" lower="-2.51327" upper="0.349066" velocity="1"/>
  </joint>
  <joint name="LWY" type="revolute">
    <origin rpy="0 -0 0" xyz="-0.022001 -0.0115 -0.041"/>
    <parent link="Body_LEP"/>
    <child link="Body_LWY"/>
    <axis xyz="0 0 1"/>
    <limit effort="10" lower="-2.79253" upper="2.79253" velocity="1"/>
  </joint>
  <joint name="LWR" type="revolute">
    <origin rpy="0 -0 0" xyz="0 0 -0.122"/>
    <parent link="Body_LWY"/>
    <child link="leftUJoint"/>
    <axis xyz="1 0 0"/>
    <limit effort="10" lower="-0.523599" upper="0.523599" velocity="1"/>
  </joint>
  <joint name="LWP" type="revolute">
    <origin rpy="0 -0 0" xyz="0 0 0"/>
    <parent link="leftUJoint"/>
    <child link="leftPalmDummy"/>
    <axis xyz="0 1 0"/>
    <limit effort="10" lower="-0.523599" upper="0.523599" velocity="1"/>
  </joint>
  <joint name="attachLeftHand" type="fixed">
    <origin rpy="0 -0 0" xyz="-0.000123302 0.00302904 -0.060093"/>
    <parent link="leftPalmDummy"/>
    <child link="leftPalm"/>
    <limit effort="10" lower="0" upper="0" velocity="1"/>
  </joint>
  <joint name="leftThumbKnuckle1" type="revolute">
    <origin rpy="-1.5708 -0.785398 -0.785398" xyz="0.0211546 -0.00655954 0.0231108"/>
    <parent link="leftPalm"/>
    <child link="leftThumbProximal"/>
    <axis xyz="0 0 -1"/>
    <limit effort="10" lower="-3.14" upper="3.14" velocity="1"/>
  </joint>
  <joint name="Knuckle234" type="revolute">
    <origin rpy="0 -0 0" xyz="0.0319998 1.5344e-07 0.00800013"/>
    <parent link="leftThumbProximal"/>
    <child link="leftThumbMedial"/>
    <axis xyz="0 0 -1"/>
    <limit effort="10" lower="-3.14" upper="3.14" velocity="1"/>
  </joint>
  <joint name="Knuckle335" type="revolute">
    <origin rpy="0 -0 0" xyz="0.022 0 0"/>
    <parent link="leftThumbMedial"/>
    <child link="leftThumbDistal"/>
    <axis xyz="0 0 -1"/>
    <limit effort="10" lower="-3.14" upper="3.14" velocity="1"/>
  </joint>
  <joint name="leftPinkyKnuckle1" type="revolute">
    <origin rpy="1.5708 0.785398 2.35619" xyz="0.018385 0.0301679 -0.00482959"/>
    <parent link="leftPalm"/>
    <child link="leftPinkyProximal"/>
    <axis xyz="0 0 -1"/>
    <limit effort="10" lower="-3.14" upper="3.14" velocity="1"/>
  </joint>
  <joint name="Knuckle237" type="revolute">
    <origin rpy="0 -0 0" xyz="0.0319998 1.5344e-07 -0.0650062"/>
    <parent link="leftPinkyProximal"/>
    <child link="leftPinkyMedial"/>
    <axis xyz="0 0 -1"/>
    <limit effort="10" lower="-3.14" upper="3.14" velocity="1"/>
  </joint>
  <joint name="Knuckle338" type="revolute">
    <origin rpy="0 -0 0" xyz="0.022 0 0"/>
    <parent link="leftPinkyMedial"/>
    <child link="leftPinkyDistal"/>
    <axis xyz="0 0 -1"/>
    <limit effort="10" lower="-3.14" upper="3.14" velocity="1"/>
  </joint>
  <joint name="leftRingKnuckle1" type="revolute">
    <origin rpy="1.5708 0.785398 2.35619" xyz="0.0183853 0.0301681 -0.00482959"/>
    <parent link="leftPalm"/>
    <child link="leftRingProximal"/>
    <axis xyz="0 0 -1"/>
    <limit effort="10" lower="-3.14" upper="3.14" velocity="1"/>
  </joint>
  <joint name="Knuckle240" type="revolute">
    <origin rpy="0 -0 0" xyz="0.0319998 1.5344e-07 -0.0460042"/>
    <parent link="leftRingProximal"/>
    <child link="leftRingMedial"/>
    <axis xyz="0 0 -1"/>
    <limit effort="10" lower="-3.14" upper="3.14" velocity="1"/>
  </joint>
  <joint name="Knuckle341" type="revolute">
    <origin rpy="0 -0 0" xyz="0.022 0 0"/>
    <parent link="leftRingMedial"/>
    <child link="leftRingDistal"/>
    <axis xyz="0 0 -1"/>
    <limit effort="10" lower="-3.14" upper="3.14" velocity="1"/>
  </joint>
  <joint name="leftMiddleKnuckle1" type="revolute">
    <origin rpy="1.5708 0.785398 2.35619" xyz="0.0183855 0.0301684 -0.00482959"/>
    <parent link="leftPalm"/>
    <child link="leftMiddleProximal"/>
    <axis xyz="0 0 -1"/>
    <limit effort="10" lower="-3.14" upper="3.14" velocity="1"/>
  </joint>
  <joint name="Knuckle243" type="revolute">
    <origin rpy="0 -0 0" xyz="0.0319998 1.5344e-07 -0.0269662"/>
    <parent link="leftMiddleProximal"/>
    <child link="leftMiddleMedial"/>
    <axis xyz="0 0 -1"/>
    <limit effort="10" lower="-3.14" upper="3.14" velocity="1"/>
  </joint>
  <joint name="Knuckle344" type="revolute">
    <origin rpy="0 -0 0" xyz="0.022 0 0"/>
    <parent link="leftMiddleMedial"/>
    <child link="leftMiddleDistal"/>
    <axis xyz="0 0 -1"/>
    <limit effort="10" lower="-3.14" upper="3.14" velocity="1"/>
  </joint>
  <joint name="leftIndexKnuckle1" type="revolute">
    <origin rpy="1.5708 0.785398 2.35619" xyz="0.0183858 0.0301686 -0.00482959"/>
    <parent link="leftPalm"/>
    <child link="leftIndexProximal"/>
    <axis xyz="0 0 -1"/>
    <limit effort="10" lower="-3.14" upper="3.14" velocity="1"/>
  </joint>
  <joint name="Knuckle2" type="revolute">
    <origin rpy="0 -0 0" xyz="0.0319998 1.5344e-07 -0.00800013"/>
    <parent link="leftIndexProximal"/>
    <child link="leftIndexMedial"/>
    <axis xyz="0 0 -1"/>
    <limit effort="10" lower="-3.14" upper="3.14" velocity="1"/>
  </joint>
  <joint name="Knuckle3" type="revolute">
    <origin rpy="0 -0 0" xyz="0.022 0 0"/>
    <parent link="leftIndexMedial"/>
    <child link="leftIndexDistal"/>
    <axis xyz="0 0 -1"/>
    <limit effort="10" lower="-3.14" upper="3.14" velocity="1"/>
  </joint>
  <joint name="HY" type="revolute">
    <origin rpy="0 -0 0" xyz="0.00549476 0.000506882 0.170924"/>
    <parent link="Torso"/>
    <child link="HeadYaw"/>
    <axis xyz="0 0 1"/>
    <limit effort="10" lower="-1.5708" upper="1.5708" velocity="1"/>
  </joint>
  <joint name="HP" type="revolute">
    <origin rpy="0 -0 0" xyz="0 0 0"/>
    <parent link="HeadYaw"/>
    <child link="Head"/>
    <axis xyz="0 1 0"/>
    <limit effort="10" lower="-1.5708" upper="1.5708" velocity="1"/>
  </joint>
  <joint name="TY" type="revolute">
    <origin rpy="0 -0 0" xyz="0.00549476 0.000506882 -0.142576"/>
    <parent link="Torso"/>
    <child link="Hip"/>
    <axis xyz="0 0 1"/>
    <limit effort="10" lower="-1.5708" upper="1.5708" velocity="1"/>
  </joint>
  <joint name="rightHipYawJoint" type="fixed">
    <origin rpy="0 -0 0" xyz="-0.0118043 -1.8681e-05 -0.0443948"/>
    <parent link="Hip"/>
    <child link="hipDummyRight"/>
    <limit effort="10" lower="0" upper="0" velocity="1"/>
  </joint>
  <joint name="RHY" type="revolute">
    <origin rpy="0 -0 0" xyz="0.0118043 -0.0884813 -0.0420582"/>
    <parent link="hipDummyRight"/>
    <child link="rightHip"/>
    <axis xyz="0 0 1"/>
    <limit effort="10" lower="-1.5708" upper="0.872665" velocity="1"/>
  </joint>
  <joint name="RHR" type="revolute">
    <origin rpy="0 -0 0" xyz="0 0 -0.091"/>
    <parent link="rightHip"/>
    <child link="rightHipPitchRoll"/>
    <axis xyz="1 0 0"/>
    <limit effort="10" lower="-1.5708" upper="0.523599" velocity="1"/>
  </joint>
  <joint name="RHP" type="revolute">
    <origin rpy="0 -0 0" xyz="0 0.054 0"/>
    <parent link="rightHipPitchRoll"/>
    <child link="rightKneeUpper"/>
    <axis xyz="0 1 0"/>
    <limit effort="10" lower="-1.5708" upper="1.5708" velocity="1"/>
  </joint>
  <joint name="RKP" type="revolute">
    <origin rpy="0 -0 0" xyz="-0.001675 -0.074999 -0.300542"/>
    <parent link="rightKneeUpper"/>
    <child link="rightKneeLower"/>
    <axis xyz="0 1 0"/>
    <limit effort="10" lower="-0.0349066" upper="2.0944" velocity="1"/>
  </joint>
  <joint name="RAP" type="revolute">
    <origin rpy="0 -0 0" xyz="4.5e-05 -0.024755 -0.299942"/>
    <parent link="rightKneeLower"/>
    <child link="rightAnklePitch"/>
    <axis xyz="0 1 0"/>
    <limit effort="10" lower="-1.74533" upper="1.74533" velocity="1"/>
  </joint>
  <joint name="RAR" type="revolute">
    <origin rpy="0 -0 0" xyz="0.071244 0.0465 -1.6e-05"/>
    <parent link="rightAnklePitch"/>
    <child link="rightFoot"/>
    <axis xyz="1 0 0"/>
    <limit effort="10" lower="-0.523599" upper="0.523599" velocity="1"/>
  </joint>
  <joint name="leftHipYawJoint" type="fixed">
    <origin rpy="0 -0 0" xyz="-0.0118043 -1.8681e-05 -0.0443948"/>
    <parent link="Hip"/>
    <child link="hipDummyLeft"/>
    <limit effort="10" lower="0" upper="0" velocity="1"/>
  </joint>
  <joint name="LHY" type="revolute">
    <origin rpy="0 -0 0" xyz="0.0118043 0.0885187 -0.0420582"/>
    <parent link="hipDummyLeft"/>
    <child link="leftHip"/>
    <axis xyz="0 0 1"/>
    <limit effort="10" lower="-0.872665" upper="1.5708" velocity="1"/>
  </joint>
  <joint name="LHR" type="revolute">
    <origin rpy="0 -0 0" xyz="0 0 -0.091"/>
    <parent link="leftHip"/>
    <child link="leftHipPitchRoll"/>
    <axis xyz="1 0 0"/>
    <limit effort="10" lower="-0.523599" upper="1.5708" velocity="1"/>
  </joint>
  <joint name="LHP" type="revolute">
    <origin rpy="0 -0 0" xyz="0 -0.054 0"/>
    <parent link="leftHipPitchRoll"/>
    <child link="leftKneeUpper"/>
    <axis xyz="0 1 0"/>
    <limit effort="10" lower="-1.5708" upper="1.5708" velocity="1"/>
  </joint>
  <joint name="LKP" type="revolute">
    <origin rpy="0 -0 0" xyz="-0.001675 0.074999 -0.300542"/>
    <parent link="leftKneeUpper"/>
    <child link="leftKneeLower"/>
    <axis xyz="0 1 0"/>
    <limit effort="10" lower="-0.0349066" upper="2.0944" velocity="1"/>
  </joint>
  <joint name="LAP" type="revolute">
    <origin rpy="0 -0 0" xyz="4.5e-05 0.024755 -0.299942"/>
    <parent link="leftKneeLower"/>
    <child link="leftAnklePitch"/>
    <axis xyz="0 1 0"/>
    <limit effort="10" lower="-1.74533" upper="1.74533" velocity="1"/>
  </joint>
  <joint name="LAR" type="revolute">
    <origin rpy="0 -0 0" xyz="0.071244 -0.0465 -1.6e-05"/>
    <parent link="leftAnklePitch"/>
    <child link="leftFoot"/>
    <axis xyz="1 0 0"/>
    <limit effort="10" lower="-0.523599" upper="0.523599" velocity="1"/>
  </joint>
</robot>

