<?xml version="1.0" ?>
<!-- =================================================================================== -->
<!-- |    This document was autogenerated by xacro from /opt/ros/jade/share/barrett_model/robots/wam4.urdf.xacro | -->
<!-- |    EDITING THIS FILE BY HAND IS NOT RECOMMENDED                                 | -->
<!-- =================================================================================== -->
<robot name="wam" xmlns:controller="http://playerstage.sourceforge.net/gazebo/xmlschema/#controller" xmlns:xacro="http://www.ros.org/wiki/xacro">
  <!-- Hollow forearm macros -->
  <!--<xacro:macro name="wam_hollow_forearm" params="prefix">-->
  <!--<joint name="${prefix}/elbow_joint" type="revolute">-->
  <!--<parent link="${prefix}/upper_arm_link"/>-->
  <!--<child link="${prefix}/forearm_link"/>-->
  <!--<origin xyz="0.045 -0.55 0" rpy="${0.5 * PI} 0 0"/>-->
  <!--<axis xyz="0 1 0"/>-->
  <!--<limit effort="15" lower="-0.9" upper="${PI}" velocity="0.50"/>-->
  <!--[> <safety_controller k_position="100" k_velocity="3" soft_lower_limit="-100.0" soft_upper_limit="100.0" /> <]-->
  <!--<dynamics damping="0.1" friction="100.0"/>-->
  <!--</joint>-->
  <!--<link name="${prefix}/forearm_link" >-->
  <!--<inertial>-->
  <!--<origin xyz="0 0 0" />-->
  <!--<mass value="3.20016804" />-->
  <!--<origin xyz="-0.04001488 -.00022942 .13271662" rpy="0 0 0" />-->
  <!--<inertia  ixx="0.01491672" ixy="0.00001741"   ixz="-0.00150604"-->
  <!--iyy="0.01482988"   iyz="-0.00002109"-->
  <!--izz="0.00294463" />-->
  <!--</inertial>-->
  <!--<visual>-->
  <!--<material name="WAMGrey">-->
  <!--<color rgba="0.7 0.7 0.7 1.0"/>-->
  <!--</material>-->
  <!--<origin xyz="0 0 0" rpy="-${PI} 0 0" />-->
  <!--<geometry>-->
  <!--<mesh filename="${models_path}/meshes/wamForeArmLink4.DAE"/>-->
  <!--</geometry>-->
  <!--</visual>-->
  <!--<collision>-->
  <!--<origin xyz="0 0 0" rpy="-${PI} 0 0" />-->
  <!--<geometry>-->
  <!--<mesh filename="${models_path}/meshes/wamForeArmLink4.stl"/>-->
  <!--</geometry>-->
  <!--</collision>-->
  <!--</link>-->
  <!--</xacro:macro>-->
  <!--<xacro:macro name="wam_hollow_wrist" params="prefix">-->
  <!--<joint name="${prefix}/UpperWristJoint" type="fixed">-->
  <!--<parent link="${prefix}/ForeArmLink"/>-->
  <!--<child link="${prefix}/LowerWristPalmLink"/>-->
  <!--<origin xyz="-0.045 0 .35" rpy="-${0.5 * PI} 0 ${0.5 * PI}"/>-->
  <!--<axis xyz="0 -1 0"/>-->
  <!--<limit effort="5" lower="-4.8" upper="1.3" velocity="0.20"/>-->
  <!--[> <safety_controller k_position="100" k_velocity="3" soft_lower_limit="-100.0" soft_upper_limit="100.0" /> <]-->
  <!--<dynamics damping="0.1" friction="100.0"/>-->
  <!--</joint>-->
  <!--<link name="${prefix}/LowerWristPalmLink" >-->
  <!--<inertial>-->
  <!--<origin xyz="0.00008921 0.00511217 0.00435824" />-->
  <!--<mass value="1.12376019" />-->
  <!--<inertia  ixx="0.00005029" ixy="0.00000020"  ixz="0.00007582"-->
  <!--iyy="0.00007582"  iyz="-0.00000359"-->
  <!--izz="0.00006270" />-->
  <!--</inertial>-->
  <!--<visual>-->
  <!--<material name="WAMGrey">-->
  <!--<color rgba="0.7 0.7 0.7 1.0"/>-->
  <!--</material>-->
  <!--<origin xyz="0 0.02711 0" rpy="${PI} 0 0" />-->
  <!--<geometry>-->
  <!--<mesh filename="${models_path}/meshes/wamUpperWristYawLink.DAE"/>-->
  <!--</geometry>-->
  <!--</visual>-->
  <!--<collision>-->
  <!--<origin xyz="0 0.02711 0" rpy="${PI} 0 0" />-->
  <!--<geometry>-->
  <!--<mesh filename="${models_path}/meshes/wamUpperWristYawLink5.stl"/>-->
  <!--</geometry>-->
  <!--</collision>-->
  <!--</link>-->
  <!--</xacro:macro>-->
  <!-- Palm with ForceTorque macros -->
  <!--<xacro:macro name="LowerWristFT" params="prefix">-->
  <!--<joint name="${prefix}/LowerWristYawJoint" type="revolute">-->
  <!--<parent link="${prefix}/UpperWristPitchLink"/>-->
  <!--<child link="${prefix}/LowerWristYawLink"/>-->
  <!--<origin xyz="0 0 0.06713340" rpy="0 0 0"/>-->
  <!--<axis xyz="0 0 1"/>-->
  <!--<limit effort="5" lower="-2.95" upper="2.95" velocity="0.20"/>[> 2.95 is a limit taken in from 3 due to saftey and differences between arms. <]-->
  <!--[> <safety_controller k_position="100" k_velocity="3" soft_lower_limit="-100.0" soft_upper_limit="100.0" /> <]-->
  <!--<dynamics damping="0.1" friction="100.0"/>-->
  <!--</joint>-->
  <!--<link name="${prefix}/LowerWristYawLink" >-->
  <!--<inertial>-->
  <!--<origin xyz="-0.00000134 -0.00228167 -0.00000141" rpy="0 0 0" />-->
  <!--<mass value="0.17286134" />-->
  <!--<inertia  ixx="0.00010859" ixy="0.00000000"  ixz="-0.00000000"-->
  <!--iyy="0.00020683"  iyz="-0.0000000"-->
  <!--izz="0.00010851" />-->
  <!--</inertial>-->
  <!--<visual>-->
  <!--<material name="WAMGrey">-->
  <!--<color rgba="0.7 0.7 0.7 1.0"/>-->
  <!--</material>-->
  <!--<origin xyz="0 0 0" rpy="0 0 0" />-->
  <!--<geometry>-->
  <!--<mesh filename="${models_path}/meshes/forceTorqueSensor.DAE"/>-->
  <!--</geometry>-->
  <!--</visual>-->
  <!--<collision>-->
  <!--<origin xyz="0 0 0" rpy="0 0 0" />-->
  <!--<geometry>-->
  <!--<mesh filename="${models_path}/meshes/forceTorqueSensor.stl"/>-->
  <!--</geometry>-->
  <!--</collision>-->
  <!--</link>-->
  <!--</xacro:macro>-->
  <!-- Hollow forearm macros -->
  <!--<xacro:macro name="wam_hollow_forearm" params="prefix">-->
  <!--<joint name="${prefix}/elbow_joint" type="revolute">-->
  <!--<parent link="${prefix}/upper_arm_link"/>-->
  <!--<child link="${prefix}/forearm_link"/>-->
  <!--<origin xyz="0.045 -0.55 0" rpy="${0.5 * PI} 0 0"/>-->
  <!--<axis xyz="0 1 0"/>-->
  <!--<limit effort="15" lower="-0.9" upper="${PI}" velocity="0.50"/>-->
  <!--[> <safety_controller k_position="100" k_velocity="3" soft_lower_limit="-100.0" soft_upper_limit="100.0" /> <]-->
  <!--<dynamics damping="0.1" friction="100.0"/>-->
  <!--</joint>-->
  <!--<link name="${prefix}/forearm_link" >-->
  <!--<inertial>-->
  <!--<origin xyz="0 0 0" />-->
  <!--<mass value="3.20016804" />-->
  <!--<origin xyz="-0.04001488 -.00022942 .13271662" rpy="0 0 0" />-->
  <!--<inertia  ixx="0.01491672" ixy="0.00001741"   ixz="-0.00150604"-->
  <!--iyy="0.01482988"   iyz="-0.00002109"-->
  <!--izz="0.00294463" />-->
  <!--</inertial>-->
  <!--<visual>-->
  <!--<material name="WAMGrey">-->
  <!--<color rgba="0.7 0.7 0.7 1.0"/>-->
  <!--</material>-->
  <!--<origin xyz="0 0 0" rpy="-${PI} 0 0" />-->
  <!--<geometry>-->
  <!--<mesh filename="${models_path}/meshes/wamForeArmLink4.DAE"/>-->
  <!--</geometry>-->
  <!--</visual>-->
  <!--<collision>-->
  <!--<origin xyz="0 0 0" rpy="-${PI} 0 0" />-->
  <!--<geometry>-->
  <!--<mesh filename="${models_path}/meshes/wamForeArmLink4.stl"/>-->
  <!--</geometry>-->
  <!--</collision>-->
  <!--</link>-->
  <!--</xacro:macro>-->
  <!--<xacro:macro name="wam_hollow_wrist" params="prefix">-->
  <!--<joint name="${prefix}/UpperWristJoint" type="fixed">-->
  <!--<parent link="${prefix}/ForeArmLink"/>-->
  <!--<child link="${prefix}/LowerWristPalmLink"/>-->
  <!--<origin xyz="-0.045 0 .35" rpy="-${0.5 * PI} 0 ${0.5 * PI}"/>-->
  <!--<axis xyz="0 -1 0"/>-->
  <!--<limit effort="5" lower="-4.8" upper="1.3" velocity="0.20"/>-->
  <!--[> <safety_controller k_position="100" k_velocity="3" soft_lower_limit="-100.0" soft_upper_limit="100.0" /> <]-->
  <!--<dynamics damping="0.1" friction="100.0"/>-->
  <!--</joint>-->
  <!--<link name="${prefix}/LowerWristPalmLink" >-->
  <!--<inertial>-->
  <!--<origin xyz="0.00008921 0.00511217 0.00435824" />-->
  <!--<mass value="1.12376019" />-->
  <!--<inertia  ixx="0.00005029" ixy="0.00000020"  ixz="0.00007582"-->
  <!--iyy="0.00007582"  iyz="-0.00000359"-->
  <!--izz="0.00006270" />-->
  <!--</inertial>-->
  <!--<visual>-->
  <!--<material name="WAMGrey">-->
  <!--<color rgba="0.7 0.7 0.7 1.0"/>-->
  <!--</material>-->
  <!--<origin xyz="0 0.02711 0" rpy="${PI} 0 0" />-->
  <!--<geometry>-->
  <!--<mesh filename="${models_path}/meshes/wamUpperWristYawLink.DAE"/>-->
  <!--</geometry>-->
  <!--</visual>-->
  <!--<collision>-->
  <!--<origin xyz="0 0.02711 0" rpy="${PI} 0 0" />-->
  <!--<geometry>-->
  <!--<mesh filename="${models_path}/meshes/wamUpperWristYawLink5.stl"/>-->
  <!--</geometry>-->
  <!--</collision>-->
  <!--</link>-->
  <!--</xacro:macro>-->
  <!-- Palm with ForceTorque macros -->
  <!--<xacro:macro name="LowerWristFT" params="prefix">-->
  <!--<joint name="${prefix}/LowerWristYawJoint" type="revolute">-->
  <!--<parent link="${prefix}/UpperWristPitchLink"/>-->
  <!--<child link="${prefix}/LowerWristYawLink"/>-->
  <!--<origin xyz="0 0 0.06713340" rpy="0 0 0"/>-->
  <!--<axis xyz="0 0 1"/>-->
  <!--<limit effort="5" lower="-2.95" upper="2.95" velocity="0.20"/>[> 2.95 is a limit taken in from 3 due to saftey and differences between arms. <]-->
  <!--[> <safety_controller k_position="100" k_velocity="3" soft_lower_limit="-100.0" soft_upper_limit="100.0" /> <]-->
  <!--<dynamics damping="0.1" friction="100.0"/>-->
  <!--</joint>-->
  <!--<link name="${prefix}/LowerWristYawLink" >-->
  <!--<inertial>-->
  <!--<origin xyz="-0.00000134 -0.00228167 -0.00000141" rpy="0 0 0" />-->
  <!--<mass value="0.17286134" />-->
  <!--<inertia  ixx="0.00010859" ixy="0.00000000"  ixz="-0.00000000"-->
  <!--iyy="0.00020683"  iyz="-0.0000000"-->
  <!--izz="0.00010851" />-->
  <!--</inertial>-->
  <!--<visual>-->
  <!--<material name="WAMGrey">-->
  <!--<color rgba="0.7 0.7 0.7 1.0"/>-->
  <!--</material>-->
  <!--<origin xyz="0 0 0" rpy="0 0 0" />-->
  <!--<geometry>-->
  <!--<mesh filename="${models_path}/meshes/forceTorqueSensor.DAE"/>-->
  <!--</geometry>-->
  <!--</visual>-->
  <!--<collision>-->
  <!--<origin xyz="0 0 0" rpy="0 0 0" />-->
  <!--<geometry>-->
  <!--<mesh filename="${models_path}/meshes/forceTorqueSensor.stl"/>-->
  <!--</geometry>-->
  <!--</collision>-->
  <!--</link>-->
  <!--</xacro:macro>-->
  <!-- Materials -->
  <material name="WAMGrey">
    <color rgba="0.7 0.7 0.7 1.0"/>
  </material>
  <!-- Root link is in the world frame-->
  <link name="world"/>
  <joint name="wam/wam_fixed_joint" type="fixed">
    <parent link="world"/>
    <child link="wam/base_link"/>
    <origin rpy="0 0 0" xyz="0.0 0.0 1"/>
  </joint>
  <link name="wam/base_link">
    <inertial>
      <origin xyz="0 0 0"/>
      <mass value="1"/>
      <inertia ixx="0.1" ixy="0" ixz="0" iyy="0.1" iyz="0" izz="0.1"/>
    </inertial>
    <visual>
      <material name="WAMGrey">
        <color rgba="0.7 0.7 0.7 0.0"/>
      </material>
      <geometry>
        <mesh filename="models/sw_meshes/base_link_fine.stl"/>
      </geometry>
    </visual>
    <collision>
      <geometry>
        <mesh filename="models/sw_meshes/base_link_convex.dae"/>
      </geometry>
    </collision>
  </link>
  <joint name="wam/base_yaw_joint" type="revolute">
    <parent link="wam/base_link"/>
    <child link="wam/shoulder_yaw_link"/>
    <origin rpy="0 0 0" xyz="0 0 0.346"/>
    <axis xyz="0 0 1"/>
    <limit effort="60" lower="-2.6" upper="2.6" velocity="2.0"/>
    <dynamics damping="1.98" friction="0"/>
  </joint>
  <gazebo reference="wam/base_yaw_joint">
    <provideFeedback>true</provideFeedback>
    <implicitSpringDamper>true</implicitSpringDamper>
    <!--<kp>0.0</kp>[> CFM <]-->
    <!--<kd>0.0</kd>[> ERP <]-->
    <!--<cfmDamping>true</cfmDamping>-->
    <!--<dynamics damping="5.5" friction="1"/>-->
  </gazebo>
  <link name="wam/shoulder_yaw_link">
    <inertial>
      <origin xyz="-.00443422 -.00066489 -0.1289039 "/>
      <mass value="5.0"/>
      <inertia ixx=".13488033" ixy="-0.00012485" ixz="0.00213041" iyy=".09046330" iyz="-.00068555" izz=".11328369"/>
    </inertial>
    <visual>
      <material name="WAMGrey">
        <color rgba="0.7 0.7 0.7 1.0"/>
      </material>
      <geometry>
        <mesh filename="models/sw_meshes/shoulder_link_fine.stl"/>
      </geometry>
    </visual>
    <collision>
      <geometry>
        <mesh filename="models/sw_meshes/shoulder_link_convex_decomposition.dae"/>
      </geometry>
    </collision>
  </link>
  <joint name="wam/shoulder_pitch_joint" type="revolute">
    <parent link="wam/shoulder_yaw_link"/>
    <child link="wam/shoulder_pitch_link"/>
    <origin rpy="-1.57079632679 0 0" xyz="0 0 0"/>
    <axis xyz="0 0 1"/>
    <limit effort="60" lower="-1.985" upper="1.985" velocity="2.0"/>
    <dynamics damping="0.55" friction="0"/>
  </joint>
  <gazebo reference="wam/shoulder_pitch_joint">
    <provideFeedback>true</provideFeedback>
    <implicitSpringDamper>true</implicitSpringDamper>
    <!--<kp>0.0</kp>[> CFM <]-->
    <!--<kd>0.0</kd>[> ERP <]-->
    <!--<cfmDamping>true</cfmDamping>-->
    <!--<dynamics damping="5.5" friction="1"/>-->
  </gazebo>
  <link name="wam/shoulder_pitch_link">
    <visual>
      <material name="WAMGrey">
        <color rgba="0.7 0.7 0.7 1.0"/>
      </material>
      <geometry>
        <mesh filename="models/sw_meshes/shoulder_pitch_link_fine.stl"/>
      </geometry>
    </visual>
    <inertial>
      <origin xyz="-.00236981 -.01542114 .03105614 "/>
      <mass value="3.87493756"/>
      <inertia ixx="0.02140958" ixy="-0.00002461" ixz="0.00027172" iyy="0.015589060" iyz="0.0018192" izz="0.01377875"/>
    </inertial>
    <collision>
      <geometry>
        <mesh filename="models/sw_meshes/shoulder_pitch_link_convex.dae"/>
      </geometry>
    </collision>
  </link>
  <joint name="wam/shoulder_yaw_joint" type="revolute">
    <parent link="wam/shoulder_pitch_link"/>
    <child link="wam/upper_arm_link"/>
    <origin rpy="1.57079632679 0 0" xyz="0 0 0"/>
    <axis xyz="0 0 1"/>
    <limit effort="45" lower="-2.8" upper="2.8" velocity="2.0"/>
    <dynamics damping="1.65" friction="0"/>
  </joint>
  <gazebo reference="wam/shoulder_yaw_joint">
    <provideFeedback>true</provideFeedback>
    <implicitSpringDamper>true</implicitSpringDamper>
    <!--<kp>0.0</kp>[> CFM <]-->
    <!--<kd>0.0</kd>[> ERP <]-->
    <!--<cfmDamping>true</cfmDamping>-->
    <!--<dynamics damping="5.5" friction="1"/>-->
  </gazebo>
  <link name="wam/upper_arm_link">
    <inertial>
      <origin xyz="0.00683258580000000 0.000033090000000 0.392492300000000"/>
      <mass value="2.20228141"/>
      <inertia ixx=".05911077" ixy="-0.00000738" ixz="-0.00249612" iyy="0.05927043" iyz="0.00001767" izz="0.0032455"/>
    </inertial>
    <visual>
      <material name="WAMGrey">
        <color rgba="0.7 0.7 0.7 1.0"/>
      </material>
      <geometry>
        <mesh filename="models/sw_meshes/upper_arm_link_fine.stl"/>
      </geometry>
    </visual>
    <collision>
      <geometry>
        <mesh filename="models/sw_meshes/upper_arm_link_convex_decomposition.dae"/>
      </geometry>
    </collision>
  </link>
  <joint name="wam/elbow_pitch_joint" type="revolute">
    <parent link="wam/upper_arm_link"/>
    <child link="wam/stump_link"/>
    <origin rpy="-1.57079632679 0 0" xyz="0.045 0 0.55"/>
    <axis xyz="0 0 1"/>
    <limit effort="15" lower="-0.9" upper="3.14159265359" velocity="2.0"/>
    <dynamics damping="0.11" friction="0"/>
  </joint>
  <link name="wam/stump_link">
    <inertial>
      <mass value="0.408"/>
      <origin rpy="0 0 0" xyz="-0.0195 -.02566 -.00022942 "/>
      <inertia ixx="0.01491672" ixy="0.001506040000000" ixz="0.000017410000000" iyy="0.002944630000000" iyz="0.000021090000000" izz="0.014829880000000"/>
    </inertial>
    <visual>
      <material name="WAMGrey">
        <color rgba="0.7 0.7 0.7 1.0"/>
      </material>
      <geometry>
        <mesh filename="models/sw_meshes/elbow_link_fine.stl"/>
      </geometry>
    </visual>
    <collision>
      <geometry>
        <mesh filename="models/sw_meshes/elbow_link_convex.dae"/>
      </geometry>
    </collision>
  </link>
</robot>
